<?xml version="1.0"?>
<robot name="mira">
    <material name="green">
        <color rgba="0 0.8 0 1"/>
    </material>
    
    <link name="base_link">
        <visual>
        <origin rpy="0 0 0" xyz="0 0 0"/>
        <geometry>
            <sphere radius="0.06"/>
        </geometry>
        </visual>
    </link>

    <link name="roll_M1_link">
        <visual>
            <origin rpy="0 0 0" xyz="0 0 0.03"/>
            <geometry>
                <box size="0.1 0.07 0.04"/>
            </geometry>
            <material name="green"/>
        </visual>
    </link>
    
    <joint name="continuous_joint" type="continuous">
        <parent link="base_link"/>
        <child link="roll_M1_link"/>
        <origin xyz="0.0023 0 -0.0005" rpy="0 0 0"/>
        <limit effort="0.1" velocity="0.005"/>
        <axis xyz="0 0 1"/>
    </joint>
  
</robot>