<?xml version="1.0"?>
<robot name="gurdy">

    <link name="base_link">
        <inertial>
            <origin xyz="0 0 0" rpy="0 0 0"/>
            <mass value="0" />
            <inertia ixx="0" ixy="0.0" ixz="0.0" iyy="0" iyz="0" izz="0"/>
        </inertial>
        <visual>
        <origin rpy="0 0 0" xyz="0 0 0"/>
        <geometry>
            <box size="0.01 0.01 0.01"/>
        </geometry>
        </visual>
        <collision>
            <origin rpy="0 0 0" xyz="0 0 0"/>
            <geometry>
                <box size="0.01 0.01 0.01"/>
            </geometry>
        <collision>
    </link>

    <gazebo reference="base_link">
        <kp>1000.0</kp>
        <kd>1000.0</kd>
        <mu1>10.0</mu1>
        <mu2>10.0</mu2>
        <material>Gazebo/Grey</material>
    </gazebo>

    <gazebo>
        <plugin name="gazebo_ros_imu_controller" filename="libgazebo_ros_imu.so">
            <robotNamespace>/gurdy</robotNamespace>
            <topicName>imu/data</topicName>
            <serviceName>imu/service</serviceName>
            <bodyName>base_link</bodyName>
            <gaussianNoise>0</gaussianNoise>
            <rpyOffsets>0 0 0</rpyOffsets>
            <updateRate>10.0</updateRate>
            <alwaysOn>true</alwaysOn>
            <gaussianNoise>0</gaussianNoise>
        </plugin>
    </gazebo>

    <joint name="fixed" type="fixed">
    	<parent link="base_link"/>
    	<child link="head_link"/>
    	<origin xyz="0 0 0" rpy="0 -0 0"/>
	</joint>
  
    <link name="head_link">
        <inertial>
            <origin xyz="0 0 0" rpy="0 0 0"/>
            <mass value="0.01" />
            <inertia ixx="7.583e-06" ixy="0.0" ixz="0.0" iyy="7.583e-06" iyz="0" izz="1.25e-05"/>
        </inertial>
        <visual>
            <origin rpy="0 0 0" xyz="0 0 0"/>
            <geometry>
                <cylinder radius="0.05" length="0.04"/>
            </geometry>
        </visual>
        <collision>
            <origin rpy="0 0 0" xyz="0 0 0"/>
            <geometry>
                <cylinder radius="0.05" length="0.04"/>
            </geometry>
        <collision>
    </link>

    <gazebo reference="head_link">
        <kp>1000.0</kp>
        <kd>1000.0</kd>
        <mu1>10.0</mu1>
        <mu2>10.0</mu2>
        <material>Gazebo/Grey</material>
    </gazebo>

    <joint name="head_upperlegM1_joint" type="continuous">
    	<parent link="head_link"/>
    	<child link="upperleg_M1_link"/>
        <origin xyz="-0.02165 -0.0125 -0.008" rpy="3.14159 -1.05879e-22 0.523599"/>
        <limit effort="0.1" velocity="0.01"/>
        <axis xyz="0 0 1"/>
	</joint>

    <transmission name="tran1">
        <type>transmission_interface/SimpleTransmission</type>
        <joint name="head_upperlegM1_joint">
            <hardwareInterface>EffortJointInterface</hardwareInterface>
        </joint>
        <actuator name="motor1">
            <hardwareInterface>EffortJointInterface</hardwareInterface>
            <mechanicalReduction>1</mechanicalReduction>
        </actuator>
    </transmission>

    <link name="upperleg_M1_link">
        <inertial>
            <origin xyz="0 0 0" rpy="0 0 0"/>
            <mass value="0.01" />
            <inertia ixx="3.01e-06" ixy="0.0" ixz="0.0" iyy="3.01e-06" iyz="0" izz="3.125e-08"/>
        </inertial>
        <visual>
            <origin rpy="0 0 0" xyz="0 0 0"/>
            <geometry>
                <cylinder radius="0.0025" length="0.06"/>
            </geometry>
        </visual>
        <collision>
            <origin rpy="0 0 0" xyz="0 0 0"/>
            <geometry>
                <cylinder radius="0.0025" length="0.06"/>
            </geometry>
        <collision>
    </link>

    <gazebo reference="upperleg_M1_link">
        <kp>1000.0</kp>
        <kd>1000.0</kd>
        <mu1>10.0</mu1>
        <mu2>10.0</mu2>
        <material>Gazebo/Grey</material>
    </gazebo>

    <joint name="upperlegM1_lowerlegM1_joint" type="continuous">
    	<parent link="upperleg_M1_link"/>
    	<child link="lowerleg_M1_link"/>
        <origin xyz="0 0.0095 0.06" rpy="0 -0 3.14159"/>
        <limit effort="0.1" velocity="0.01"/>
        <axis xyz="0 0 1"/>
	</joint>

    <transmission name="tran2">
        <type>transmission_interface/SimpleTransmission</type>
        <joint name="upperlegM1_lowerlegM1_joint">
            <hardwareInterface>EffortJointInterface</hardwareInterface>
        </joint>
        <actuator name="motor2">
            <hardwareInterface>EffortJointInterface</hardwareInterface>
            <mechanicalReduction>1</mechanicalReduction>
        </actuator>
    </transmission>

    <link name="lowerleg_M1_link">
        <inertial>
            <origin xyz="0 0 0" rpy="0 0 0"/>
            <mass value="0.01" />
            <inertia ixx="3.005625e-06" ixy="0.0" ixz="0.0" iyy="3.005625e-06" iyz="0" izz="1.125e-08"/>
        </inertial>
        <visual>
            <origin rpy="0 0 0" xyz="0 0 0"/>
            <geometry>
                <cylinder radius="0.0015" length="0.06"/>
            </geometry>
        </visual>
        <collision>
            <origin rpy="0 0 0" xyz="0 0 0"/>
            <geometry>
                <cylinder radius="0.0015" length="0.06"/>
            </geometry>
        <collision>
    </link>

    <gazebo reference="lowerleg_M1_link">
        <kp>1000.0</kp>
        <kd>1000.0</kd>
        <mu1>10.0</mu1>
        <mu2>10.0</mu2>
        <material>Gazebo/Grey</material>
    </gazebo>

    <joint name="basefoot_peg_M1_basefoot_peg_M1_joint_joint" type="fixed">
    	<parent link="lowerleg_M1_link"/>
    	<child link="footM1_link"/>
    	<origin xyz="0 0 0.06" rpy="0 -0 0"/>
	</joint>

    <link name="footM1_link">
        <inertial>
            <origin xyz="0 0 0" rpy="0 0 0"/>
            <mass value="0.01" />
            <inertia ixx="2.56e-07" ixy="0.0" ixz="0.0" iyy="2.56e-07" iyz="0" izz="2.56e-07"/>
        </inertial>
        <visual>
            <origin rpy="0 0 0" xyz="0 0 0"/>
            <geometry>
                <sphere radius="0.008"/>
            </geometry>
        </visual>
        <collision>
            <origin rpy="0 0 0" xyz="0 0 0"/>
            <geometry>
                <sphere radius="0.008"/>
            </geometry>
        <collision>
    </link>

    <gazebo reference="footM1_link">
        <kp>1000.0</kp>
        <kd>1000.0</kd>
        <mu1>10.0</mu1>
        <mu2>10.0</mu2>
        <material>Gazebo/Grey</material>
    </gazebo>

    <joint name="head_upperlegM2_joint" type="continuous">
    	<parent link="head_link"/>
    	<child link="upperleg_M2_link"/>
        <origin xyz="-0.02165 -0.0125 -0.008" rpy="3.14159 -0 2.61799"/>
        <limit effort="0.1" velocity="0.01"/>
        <axis xyz="0 0 1"/>
	</joint>

    <transmission name="tran3">
        <type>transmission_interface/SimpleTransmission</type>
        <joint name="head_upperlegM2_joint">
            <hardwareInterface>EffortJointInterface</hardwareInterface>
        </joint>
        <actuator name="motor3">
            <hardwareInterface>EffortJointInterface</hardwareInterface>
            <mechanicalReduction>1</mechanicalReduction>
        </actuator>
    </transmission>

    <link name="upperleg_M2_link">
        <inertial>
            <origin xyz="0 0 0" rpy="0 0 0"/>
            <mass value="0.01" />
            <inertia ixx="3.01e-06" ixy="0.0" ixz="0.0" iyy="3.01e-06" iyz="0" izz="3.125e-08"/>
        </inertial>
        <visual>
            <origin rpy="0 0 0" xyz="0 0 0"/>
            <geometry>
                <cylinder radius="0.0025" length="0.06"/>
            </geometry>
        </visual>
        <collision>
            <origin rpy="0 0 0" xyz="0 0 0"/>
            <geometry>
                <cylinder radius="0.0025" length="0.06"/>
            </geometry>
        <collision>
    </link>

    <gazebo reference="upperleg_M2_link">
        <kp>1000.0</kp>
        <kd>1000.0</kd>
        <mu1>10.0</mu1>
        <mu2>10.0</mu2>
        <material>Gazebo/Grey</material>
    </gazebo>

    <joint name="upperlegM2_lowerlegM2_joint" type="continuous">
    	<parent link="upperleg_M2_link"/>
    	<child link="lowerleg_M2_link"/>
        <origin xyz="0 0.0095 0.06" rpy="0 -0 3.14159"/>
        <limit effort="0.1" velocity="0.01"/>
        <axis xyz="0 0 1"/>
	</joint>

    <transmission name="tran4">
        <type>transmission_interface/SimpleTransmission</type>
        <joint name="upperlegM2_lowerlegM2_joint">
            <hardwareInterface>EffortJointInterface</hardwareInterface>
        </joint>
        <actuator name="motor4">
            <hardwareInterface>EffortJointInterface</hardwareInterface>
            <mechanicalReduction>1</mechanicalReduction>
        </actuator>
    </transmission>

    <link name="lowerleg_M2_link">
        <inertial>
            <origin xyz="0 0 0" rpy="0 0 0"/>
            <mass value="0.01" />
            <inertia ixx="3.005625e-06" ixy="0.0" ixz="0.0" iyy="3.005625e-06" iyz="0" izz="1.125e-08"/>
        </inertial>
        <visual>
            <origin rpy="0 0 0" xyz="0 0 0"/>
            <geometry>
                <cylinder radius="0.0015" length="0.06"/>
            </geometry>
        </visual>
        <collision>
            <origin rpy="0 0 0" xyz="0 0 0"/>
            <geometry>
                <cylinder radius="0.0015" length="0.06"/>
            </geometry>
        <collision>
    </link>

    <gazebo reference="lowerleg_M2_link">
        <kp>1000.0</kp>
        <kd>1000.0</kd>
        <mu1>10.0</mu1>
        <mu2>10.0</mu2>
        <material>Gazebo/Grey</material>
    </gazebo>

    <joint name="basefoot_peg_M2_basefoot_peg_M2_joint_joint" type="fixed">
    	<parent link="lowerleg_M2_link"/>
    	<child link="footM2_link"/>
    	<origin xyz="0 0 0.06" rpy="0 -0 0"/>
	</joint>

    <link name="footM2_link">
        <inertial>
            <origin xyz="0 0 0" rpy="0 0 0"/>
            <mass value="0.01" />
            <inertia ixx="2.56e-07" ixy="0.0" ixz="0.0" iyy="2.56e-07" iyz="0" izz="2.56e-07"/>
        </inertial>
        <visual>
            <origin rpy="0 0 0" xyz="0 0 0"/>
            <geometry>
                <sphere radius="0.008"/>
            </geometry>
        </visual>
        <collision>
            <origin rpy="0 0 0" xyz="0 0 0"/>
            <geometry>
                <sphere radius="0.008"/>
            </geometry>
        <collision>
    </link>

    <gazebo reference="footM2_link">
        <kp>1000.0</kp>
        <kd>1000.0</kd>
        <mu1>10.0</mu1>
        <mu2>10.0</mu2>
        <material>Gazebo/Grey</material>
    </gazebo>

    <joint name="head_upperlegM3_joint" type="continuous">
    	<parent link="head_link"/>
    	<child link="upperleg_M3_link"/>
        <origin xyz="0 0.025 -0.008" rpy="3.14159 -0 -1.5708"/>
        <limit effort="0.1" velocity="0.01"/>
        <axis xyz="0 0 1"/>
	</joint>

    <transmission name="tran5">
        <type>transmission_interface/SimpleTransmission</type>
        <joint name="head_upperlegM3_joint">
            <hardwareInterface>EffortJointInterface</hardwareInterface>
        </joint>
        <actuator name="motor5">
            <hardwareInterface>EffortJointInterface</hardwareInterface>
            <mechanicalReduction>1</mechanicalReduction>
        </actuator>
    </transmission>

    <link name="upperleg_M3_link">
        <inertial>
            <origin xyz="0 0 0" rpy="0 0 0"/>
            <mass value="0.01" />
            <inertia ixx="3.01e-06" ixy="0.0" ixz="0.0" iyy="3.01e-06" iyz="0" izz="3.125e-08"/>
        </inertial>
        <visual>
            <origin rpy="0 0 0" xyz="0 0 0"/>
            <geometry>
                <cylinder radius="0.0025" length="0.06"/>
            </geometry>
        </visual>
        <collision>
            <origin rpy="0 0 0" xyz="0 0 0"/>
            <geometry>
                <cylinder radius="0.0025" length="0.06"/>
            </geometry>
        <collision>
    </link>

    <gazebo reference="upperleg_M3_link">
        <kp>1000.0</kp>
        <kd>1000.0</kd>
        <mu1>10.0</mu1>
        <mu2>10.0</mu2>
        <material>Gazebo/Grey</material>
    </gazebo>

    <joint name="upperlegM3_lowerlegM3_joint" type="continuous">
    	<parent link="upperleg_M3_link"/>
    	<child link="lowerleg_M3_link"/>
        <origin xyz="0 0.0095 0.06" rpy="0 -0 3.14159"/>
        <limit effort="0.1" velocity="0.01"/>
        <axis xyz="0 0 1"/>
	</joint>

    <transmission name="tran6">
        <type>transmission_interface/SimpleTransmission</type>
        <joint name="upperlegM3_lowerlegM3_joint">
            <hardwareInterface>EffortJointInterface</hardwareInterface>
        </joint>
        <actuator name="motor6">
            <hardwareInterface>EffortJointInterface</hardwareInterface>
            <mechanicalReduction>1</mechanicalReduction>
        </actuator>
    </transmission>

    <link name="lowerleg_M3_link">
        <inertial>
            <origin xyz="0 0 0" rpy="0 0 0"/>
            <mass value="0.01" />
            <inertia ixx="3.005625e-06" ixy="0.0" ixz="0.0" iyy="3.005625e-06" iyz="0" izz="1.125e-08"/>
        </inertial>
        <visual>
            <origin rpy="0 0 0" xyz="0 0 0"/>
            <geometry>
                <cylinder radius="0.0015" length="0.06"/>
            </geometry>
        </visual>
        <collision>
            <origin rpy="0 0 0" xyz="0 0 0"/>
            <geometry>
                <cylinder radius="0.0015" length="0.06"/>
            </geometry>
        <collision>
    </link>

    <gazebo reference="lowerleg_M3_link">
        <kp>1000.0</kp>
        <kd>1000.0</kd>
        <mu1>10.0</mu1>
        <mu2>10.0</mu2>
        <material>Gazebo/Grey</material>
    </gazebo>

    <joint name="basefoot_peg_M3_basefoot_peg_M3_joint_joint" type="fixed">
    	<parent link="lowerleg_M3_link"/>
    	<child link="footM3_link"/>
    	<origin xyz="0 0 0.06" rpy="0 -0 0"/>
	</joint>

    <link name="footM3_link">
        <inertial>
            <origin xyz="0 0 0" rpy="0 0 0"/>
            <mass value="0.01" />
            <inertia ixx="2.56e-07" ixy="0.0" ixz="0.0" iyy="2.56e-07" iyz="0" izz="2.56e-07"/>
        </inertial>
        <visual>
            <origin rpy="0 0 0" xyz="0 0 0"/>
            <geometry>
                <sphere radius="0.008"/>
            </geometry>
        </visual>
        <collision>
            <origin rpy="0 0 0" xyz="0 0 0"/>
            <geometry>
                <sphere radius="0.008"/>
            </geometry>
        <collision>
    </link>

    <gazebo reference="footM3_link">
        <kp>1000.0</kp>
        <kd>1000.0</kd>
        <mu1>10.0</mu1>
        <mu2>10.0</mu2>
        <material>Gazebo/Grey</material>
    </gazebo>

</robot>